<?xml version="1.0"?>
<robot name="functional_quadruped">

  <link name="torso">
    <visual>
      <origin xyz="0 0 0" rpy="0 0 0"/>
      <geometry>
        <box size="0.4 0.15 0.1"/> 
      </geometry>
      <material name="gray">
        <color rgba="0.4 0.4 0.4 1.0"/>
      </material>
    </visual>
    <collision>
      <origin xyz="0 0 0" rpy="0 0 0"/>
      <geometry>
        <box size="0.4 0.15 0.1"/>
      </geometry>
    </collision>
    <inertial>
      <origin xyz="0 0 0" rpy="0 0 0"/>
      <mass value="4.0"/>
      <inertia
        ixx="0.02" ixy="0.0" ixz="0.0"
        iyy="0.03" iyz="0.0"
        izz="0.01"/>
    </inertial>
  </link>

  <!-- 腿部设计 - 现在有前后运动能力 -->
  <link name="front_left_leg">
    <visual>
      <origin xyz="0 0 -0.075" rpy="0 0 0"/>
      <geometry>
        <box size="0.05 0.05 0.15"/>
      </geometry>
      <material name="red">
        <color rgba="0.8 0.2 0.2 1.0"/>
      </material>
    </visual>
    <collision>
      <origin xyz="0 0 -0.075" rpy="0 0 0"/>
      <geometry>
        <box size="0.05 0.05 0.15"/>
      </geometry>
      <surface>
        <friction>
          <lateral_friction value="1.5"/>  <!-- 增加横向摩擦系数 -->
          <rolling_friction value="0.1"/> <!-- 新增滚动摩擦系数 -->
        </friction>
      </surface>
    </collision>
    <inertial>
      <origin xyz="0 0 -0.075" rpy="0 0 0"/>
      <mass value="0.5"/>
      <inertia
        ixx="0.001" ixy="0.0" ixz="0.0"
        iyy="0.001" iyz="0.0"
        izz="0.0001"/>
    </inertial>
  </link>

  <link name="front_right_leg">
    <visual>
      <origin xyz="0 0 -0.075" rpy="0 0 0"/>
      <geometry>
        <box size="0.05 0.05 0.15"/>
      </geometry>
      <material name="red">
        <color rgba="0.8 0.2 0.2 1.0"/>
      </material>
    </visual>
    <collision>
      <origin xyz="0 0 -0.075" rpy="0 0 0"/>
      <geometry>
        <box size="0.05 0.05 0.15"/>
      </geometry>
      <surface>
        <friction>
          <lateral_friction value="1.5"/>  <!-- 增加横向摩擦系数 -->
          <rolling_friction value="0.1"/> <!-- 新增滚动摩擦系数 -->
        </friction>
      </surface>
    </collision>
    <inertial>
      <origin xyz="0 0 -0.075" rpy="0 0 0"/>
      <mass value="0.5"/>
      <inertia
        ixx="0.001" ixy="0.0" ixz="0.0"
        iyy="0.001" iyz="0.0"
        izz="0.0001"/>
    </inertial>
  </link>

  <link name="rear_left_leg">
    <visual>
      <origin xyz="0 0 -0.075" rpy="0 0 0"/>
      <geometry>
        <box size="0.05 0.05 0.15"/>
      </geometry>
      <material name="blue">
        <color rgba="0.2 0.2 0.8 1.0"/>
      </material>
    </visual>
    <collision>
      <origin xyz="0 0 -0.075" rpy="0 0 0"/>
      <geometry>
        <box size="0.05 0.05 0.15"/>
      </geometry>
      <surface>
        <friction>
          <lateral_friction value="1.5"/>  <!-- 增加横向摩擦系数 -->
          <rolling_friction value="0.1"/> <!-- 新增滚动摩擦系数 -->
        </friction>
      </surface>
    </collision>
    <inertial>
      <origin xyz="0 0 -0.075" rpy="0 0 0"/>
      <mass value="0.5"/>
      <inertia
        ixx="0.001" ixy="0.0" ixz="0.0"
        iyy="0.001" iyz="0.0"
        izz="0.0001"/>
    </inertial>
  </link>

  <link name="rear_right_leg">
    <visual>
      <origin xyz="0 0 -0.075" rpy="0 0 0"/>
      <geometry>
        <box size="0.05 0.05 0.15"/>
      </geometry>
      <material name="blue">
        <color rgba="0.2 0.2 0.8 1.0"/>
      </material>
    </visual>
    <collision>
      <origin xyz="0 0 -0.075" rpy="0 0 0"/>
      <geometry>
        <box size="0.05 0.05 0.15"/>
      </geometry>
      <surface>
        <friction>
          <lateral_friction value="1.5"/>  <!-- 增加横向摩擦系数 -->
          <rolling_friction value="0.1"/> <!-- 新增滚动摩擦系数 -->
        </friction>
      </surface>
    </collision>
    <inertial>
      <origin xyz="0 0 -0.075" rpy="0 0 0"/>
      <mass value="0.5"/>
      <inertia
        ixx="0.001" ixy="0.0" ixz="0.0"
        iyy="0.001" iyz="0.0"
        izz="0.0001"/>
    </inertial>
  </link>

  <!-- 关键修改：关节旋转轴改为前后方向 -->
  <!-- 前腿关节 - 绕Y轴旋转 -->
  <joint name="front_left_leg_joint" type="revolute">
    <parent link="torso"/>
    <child link="front_left_leg"/>
    <origin xyz="0.150 0.075 -0.05" rpy="0 0 0"/>
    <axis xyz="0 1 0"/>
    <limit lower="-1.0" upper="1.0" effort="100" velocity="2.0"/>
  </joint>

  <joint name="front_right_leg_joint" type="revolute">
    <parent link="torso"/>
    <child link="front_right_leg"/>
    <origin xyz="0.150 -0.075 -0.05" rpy="0 0 0"/>
    <axis xyz="0 1 0"/>
    <limit lower="-1.0" upper="1.0" effort="100" velocity="2.0"/>
  </joint>

  <!-- 后腿关节 - 绕Y轴旋转 -->
  <joint name="rear_left_leg_joint" type="revolute">
    <parent link="torso"/>
    <child link="rear_left_leg"/>
    <origin xyz="-0.150 0.075 -0.05" rpy="0 0 0"/>
    <axis xyz="0 1 0"/>
    <limit lower="-1.0" upper="1.0" effort="100" velocity="2.0"/>
  </joint>

  <joint name="rear_right_leg_joint" type="revolute">
    <parent link="torso"/>
    <child link="rear_right_leg"/>
    <origin xyz="-0.150 -0.075 -0.05" rpy="0 0 0"/>
    <axis xyz="0 1 0"/>
    <limit lower="-1.0" upper="1.0" effort="100" velocity="2.0"/>
  </joint>

</robot>